Workbook

Sheet master
A1: Property | B1: Sqft | C1: Bedrooms | D1: Bathrooms | E1: Hood | F1: Owner First | G1: Arrival | H1: Departure | I1: Daily/Nightly Rate | J1: Created | K1: Parking | L1: Pets Allowed
A2: Testing street NW Unit 123, testing city, DC 22209 | B2: =_xlfn.XLOOKUP(A2, 'sqft data'!A:A, 'sqft data'!C:C, "Not Found") -> Not Found | C2: =_xlfn.XLOOKUP(A2, 'bedroom data'!A:A, 'bedroom data'!B:B, "Not Found") -> 1 | D2: =_xlfn.XLOOKUP(A2, 'bathroom data'!A:A, 'bathroom data'!B:B, "Not Found") -> 1 | E2: =_xlfn.XLOOKUP(A2, 'bedroom data'!A:A, 'bedroom data'!C:C, "Not Found") -> Arlington | F2: Animesh | G2: Aug 26, 2025 | H2: Nov 19, 2025 | I2: 287.96 | J2: Aug 25, 2025 | K2: No | L2: No
A3: Testing Property Unit 222, Washington, DC 20003 | B3: =_xlfn.XLOOKUP(A3, 'sqft data'!A:A, 'sqft data'!C:C, "Not Found") -> Not Found | C3: =_xlfn.XLOOKUP(A3, 'bedroom data'!A:A, 'bedroom data'!B:B, "Not Found") -> 2 | D3: =_xlfn.XLOOKUP(A3, 'bathroom data'!A:A, 'bathroom data'!B:B, "Not Found") -> 3 | E3: =_xlfn.XLOOKUP(A3, 'bedroom data'!A:A, 'bedroom data'!C:C, "Not Found") -> Alexandria | F3: tester | G3: Aug 01, 2025 | H3: Oct 01, 2025 | I3: 200 | J3: Aug 19, 2025 | K3: No | L3: No
A4: SOJOURN: 1716 17th Street NW Unit 301, Washington, DC 20009 | B4: =_xlfn.XLOOKUP(A4, 'sqft data'!A:A, 'sqft data'!C:C, "Not Found") -> Not Found | C4: =_xlfn.XLOOKUP(A4, 'bedroom data'!A:A, 'bedroom data'!B:B, "Not Found") -> Studio | D4: =_xlfn.XLOOKUP(A4, 'bathroom data'!A:A, 'bathroom data'!B:B, "Not Found") -> 1 | E4: =_xlfn.XLOOKUP(A4, 'bedroom data'!A:A, 'bedroom data'!C:C, "Not Found") -> Dupont Circle | F4: Jessica | G4: Jun 10, 2025 | H4: Jul 14, 2025 | I4: 0 | J4: Jun 01, 2025 | K4: No | L4: No
A5: SOJOURN: 1716 17th Street NW Unit 301, Washington, DC 20009 | B5: =_xlfn.XLOOKUP(A5, 'sqft data'!A:A, 'sqft data'!C:C, "Not Found") -> Not Found | C5: =_xlfn.XLOOKUP(A5, 'bedroom data'!A:A, 'bedroom data'!B:B, "Not Found") -> Studio | D5: =_xlfn.XLOOKUP(A5, 'bathroom data'!A:A, 'bathroom data'!B:B, "Not Found") -> 1 | E5: =_xlfn.XLOOKUP(A5, 'bedroom data'!A:A, 'bedroom data'!C:C, "Not Found") -> Dupont Circle | F5: Jessica | G5: Jul 28, 2025 | H5: Aug 16, 2025 | I5: 0 | J5: Jun 15, 2025 | K5: No | L5: No
A6: SOJOURN: 1716 17th Street NW Unit 102, Washington, DC 20009 | B6: =_xlfn.XLOOKUP(A6, 'sqft data'!A:A, 'sqft data'!C:C, "Not Found") -> Not Found | C6: =_xlfn.XLOOKUP(A6, 'bedroom data'!A:A, 'bedroom data'!B:B, "Not Found") -> 1 | D6: =_xlfn.XLOOKUP(A6, 'bathroom data'!A:A, 'bathroom data'!B:B, "Not Found") -> 1 | E6: =_xlfn.XLOOKUP(A6, 'bedroom data'!A:A, 'bedroom data'!C:C, "Not Found") -> Dupont Circle | F6: Jessica | G6: Dec 13, 2025 | H6: Dec 14, 2025 | I6: 0 | J6: Nov 20, 2024 | K6: No | L6: No
A7: DO NOT USE xxxx218 E St. NE NE Unit 1AB, Washington, DC 20002 | B7: =_xlfn.XLOOKUP(A7, 'sqft data'!A:A, 'sqft data'!C:C, "Not Found") -> Not Found | C7: =_xlfn.XLOOKUP(A7, 'bedroom data'!A:A, 'bedroom data'!B:B, "Not Found") -> 3 | D7: =_xlfn.XLOOKUP(A7, 'bathroom data'!A:A, 'bathroom data'!B:B, "Not Found") -> 3.5 | E7: =_xlfn.XLOOKUP(A7, 'bedroom data'!A:A, 'bedroom data'!C:C, "Not Found") -> Capitol Hill | F7: Aine | G7: May 01, 2025 | H7: Oct 31, 2025 | I7: 112984 | J7: Mar 28, 2025 | K7: Yes | L7: Yes
A8: DO NOT USE 1766 T Street, NW, Unit 1AB, Washington, DC 20009 | B8: =_xlfn.XLOOKUP(A8, 'sqft data'!A:A, 'sqft data'!C:C, "Not Found") -> Not Found | C8: =_xlfn.XLOOKUP(A8, 'bedroom data'!A:A, 'bedroom data'!B:B, "Not Found") -> 3 | D8: =_xlfn.XLOOKUP(A8, 'bathroom data'!A:A, 'bathroom data'!B:B, "Not Found") -> 2.5 | E8: =_xlfn.XLOOKUP(A8, 'bedroom data'!A:A, 'bedroom data'!C:C, "Not Found") -> Dupont Circle | F8: Carol | G8: Mar 01, 2025 | H8: Aug 31, 2025 | I8: 105 | J8: Feb 23, 2025 | K8: No | L8: No
A9: DO NOT USE - 5225 Macomb NW Unit B, Washington, DC 20016 | B9: =_xlfn.XLOOKUP(A9, 'sqft data'!A:A, 'sqft data'!C:C, "Not Found") -> Not Found | C9: =_xlfn.XLOOKUP(A9, 'bedroom data'!A:A, 'bedroom data'!B:B, "Not Found") -> 1 | D9: =_xlfn.XLOOKUP(A9, 'bathroom data'!A:A, 'bathroom data'!B:B, "Not Found") -> 1 | E9: =_xlfn.XLOOKUP(A9, 'bedroom data'!A:A, 'bedroom data'!C:C, "Not Found") -> Palisades | F9: Tim | G9: Jul 01, 2025 | H9: Sep 30, 2025 | I9: 100 | J9: Feb 13, 2025 | K9: No | L9: No
A10: 936 T Street NW Unit #B, Washington, DC 20001 | B10: =_xlfn.XLOOKUP(A10, 'sqft data'!A:A, 'sqft data'!C:C, "Not Found") -> Not Found | C10: =_xlfn.XLOOKUP(A10, 'bedroom data'!A:A, 'bedroom data'!B:B, "Not Found") -> 1 | D10: =_xlfn.XLOOKUP(A10, 'bathroom data'!A:A, 'bathroom data'!B:B, "Not Found") -> 1 | E10: =_xlfn.XLOOKUP(A10, 'bedroom data'!A:A, 'bedroom data'!C:C, "Not Found") -> U Street Corridor | F10: Hershel | G10: Mar 24, 2025 | H10: Dec 25, 2025 | I10: 0 | J10: Dec 24, 2024 | K10: No | L10: No
A11: 922 24th Street NW Unit 515, Washington, DC 20037 | B11: =_xlfn.XLOOKUP(A11, 'sqft data'!A:A, 'sqft data'!C:C, "Not Found") -> 520 | C11: =_xlfn.XLOOKUP(A11, 'bedroom data'!A:A, 'bedroom data'!B:B, "Not Found") -> 1 | D11: =_xlfn.XLOOKUP(A11, 'bathroom data'!A:A, 'bathroom data'!B:B, "Not Found") -> 1 | E11: =_xlfn.XLOOKUP(A11, 'bedroom data'!A:A, 'bedroom data'!C:C, "Not Found") -> Foggy Bottom | F11: Ashley | G11: Jan 28, 2025 | H11: Jul 26, 2025 | I11: 85.38 | J11: Jan 22, 2025 | K11: No | L11: No
A12: 922 24th Street NW Unit 515, Washington, DC 20037 | B12: =_xlfn.XLOOKUP(A12, 'sqft data'!A:A, 'sqft data'!C:C, "Not Found") -> 520 | C12: =_xlfn.XLOOKUP(A12, 'bedroom data'!A:A, 'bedroom data'!B:B, "Not Found") -> 1 | D12: =_xlfn.XLOOKUP(A12, 'bathroom data'!A:A, 'bathroom data'!B:B, "Not Found") -> 1 | E12: =_xlfn.XLOOKUP(A12, 'bedroom data'!A:A, 'bedroom data'!C:C, "Not Found") -> Foggy Bottom | F12: Ashley | G12: Feb 08, 2026 | H12: Aug 31, 2026 | I12: 88 | J12: Jan 26, 2026 | K12: No | L12: No
A13: 921 South Carolina Avenue SE Unit House, Washington, DC 20003 | B13: =_xlfn.XLOOKUP(A13, 'sqft data'!A:A, 'sqft data'!C:C, "Not Found") -> 1450 | C13: =_xlfn.XLOOKUP(A13, 'bedroom data'!A:A, 'bedroom data'!B:B, "Not Found") -> 3 | D13: =_xlfn.XLOOKUP(A13, 'bathroom data'!A:A, 'bathroom data'!B:B, "Not Found") -> 1.5 | E13: =_xlfn.XLOOKUP(A13, 'bedroom data'!A:A, 'bedroom data'!C:C, "Not Found") -> Capitol Hill | F13: Zachary | G13: Mar 22, 2025 | H13: Jul 04, 2025 | I13: 208 | J13: Mar 10, 2025 | K13: No | L13: No
... A59: 800 East Capitol NE Unit 1, Washington, DC 20003 | B59: =_xlfn.XLOOKUP(A59, 'sqft data'!A:A, 'sqft data'!C:C, "Not Found") -> 800 | C59: =_xlfn.XLOOKUP(A59, 'bedroom data'!A:A, 'bedroom data'!B:B, "Not Found") -> 1 | D59: =_xlfn.XLOOKUP(A59, 'bathroom data'!A:A, 'bathroom data'!B:B, "Not Found") -> 1 | E59: =_xlfn.XLOOKUP(A59, 'bedroom data'!A:A, 'bedroom data'!C:C, "Not Found") -> Capitol Hill | F59: Karen | G59: May 01, 2026 | H59: Aug 28, 2026 | I59: 109 | J59: Apr 06, 2026 | K59: Yes | L59: No
A60: 800 East Capitol Street NE Unit House, Washington, DC 20003 | B60: =_xlfn.XLOOKUP(A60, 'sqft data'!A:A, 'sqft data'!C:C, "Not Found") -> 3900 | C60: =_xlfn.XLOOKUP(A60, 'bedroom data'!A:A, 'bedroom data'!B:B, "Not Found") -> 4 | D60: 4.5 | E60: =_xlfn.XLOOKUP(A60, 'bedroom data'!A:A, 'bedroom data'!C:C, "Not Found") -> Capitol Hill | F60: Karen | G60: Dec 03, 2023 | H60: Jun 30, 2027 | I60: 250 | J60: Nov 17, 2023 | K60: No | L60: No
A61: 777 7th Street NW Unit 1117, Washington, DC 20001 | B61: =_xlfn.XLOOKUP(A61, 'sqft data'!A:A, 'sqft data'!C:C, "Not Found") -> 750 | C61: =_xlfn.XLOOKUP(A61, 'bedroom data'!A:A, 'bedroom data'!B:B, "Not Found") -> 1 | D61: =_xlfn.XLOOKUP(A61, 'bathroom data'!A:A, 'bathroom data'!B:B, "Not Found") -> 1 | E61: =_xlfn.XLOOKUP(A61, 'bedroom data'!A:A, 'bedroom data'!C:C, "Not Found") -> Penn Quarter | F61: Richard | G61: Aug 30, 2025 | H61: Aug 30, 2027 | I61: 100 | J61: Aug 14, 2025 | K61: No | L61: No
A62: 731 20th Street South Unit 1, Arlington, VA 22202 | B62: =_xlfn.XLOOKUP(A62, 'sqft data'!A:A, 'sqft data'!C:C, "Not Found") -> Not Found | C62: =_xlfn.XLOOKUP(A62, 'bedroom data'!A:A, 'bedroom data'!B:B, "Not Found") -> 3 | D62: =_xlfn.XLOOKUP(A62, 'bathroom data'!A:A, 'bathroom data'!B:B, "Not Found") -> 3 | E62: =_xlfn.XLOOKUP(A62, 'bedroom data'!A:A, 'bedroom data'!C:C, "Not Found") -> Arlington | F62: Allen | G62: Jan 26, 2025 | H62: Sep 24, 2025 | I62: 220 | J62: May 13, 2025 | K62: Yes | L62: Yes
A63: 725 5th Street SE Unit 23, Washington, DC 20003 | B63: =_xlfn.XLOOKUP(A63, 'sqft data'!A:A, 'sqft data'!C:C, "Not Found") -> 1800 | C63: =_xlfn.XLOOKUP(A63, 'bedroom data'!A:A, 'bedroom data'!B:B, "Not Found") -> 2 | D63: =_xlfn.XLOOKUP(A63, 'bathroom data'!A:A, 'bathroom data'!B:B, "Not Found") -> 2 | E63: =_xlfn.XLOOKUP(A63, 'bedroom data'!A:A, 'bedroom data'!C:C, "Not Found") -> Capitol Hill | F63: Justin | G63: Jul 30, 2025 | H63: Jan 31, 2026 | I63: 264 | J63: Jul 30, 2025 | K63: No | L63: No
A64: 725 5th Street SE Unit 23, Washington, DC 20003 | B64: =_xlfn.XLOOKUP(A64, 'sqft data'!A:A, 'sqft data'!C:C, "Not Found") -> 1800 | C64: =_xlfn.XLOOKUP(A64, 'bedroom data'!A:A, 'bedroom data'!B:B, "Not Found") -> 2 | D64: =_xlfn.XLOOKUP(A64, 'bathroom data'!A:A, 'bathroom data'!B:B, "Not Found") -> 2 | E64: =_xlfn.XLOOKUP(A64, 'bedroom data'!A:A, 'bedroom data'!C:C, "Not Found") -> Capitol Hill | F64: Justin | G64: Jun 06, 2026 | H64: Jul 24, 2026 | I64: 264 | J64: May 21, 2026 | K64: No | L64: No
A65: 723 5th Street NE Unit House, Washington, DC 20002 | B65: =_xlfn.XLOOKUP(A65, 'sqft data'!A:A, 'sqft data'!C:C, "Not Found") -> 3000 | C65: =_xlfn.XLOOKUP(A65, 'bedroom data'!A:A, 'bedroom data'!B:B, "Not Found") -> 3 | D65: =_xlfn.XLOOKUP(A65, 'bathroom data'!A:A, 'bathroom data'!B:B, "Not Found") -> 2.5 | E65: =_xlfn.XLOOKUP(A65, 'bedroom data'!A:A, 'bedroom data'!C:C, "Not Found") -> Capitol Hill | F65: Linda | G65: Jun 26, 2025 | H65: Jul 04, 2025 | I65: 0 | J65: Jun 26, 2025 | K65: No | L65: No
A66: 723 5th Street NE Unit House, Washington, DC 20002 | B66: =_xlfn.XLOOKUP(A66, 'sqft data'!A:A, 'sqft data'!C:C, "Not Found") -> 3000 | C66: =_xlfn.XLOOKUP(A66, 'bedroom data'!A:A, 'bedroom data'!B:B, "Not Found") -> 3 | D66: =_xlfn.XLOOKUP(A66, 'bathroom data'!A:A, 'bathroom data'!B:B, "Not Found") -> 2.5 | E66: =_xlfn.XLOOKUP(A66, 'bedroom data'!A:A, 'bedroom data'!C:C, "Not Found") -> Capitol Hill | F66: Linda | G66: Jul 13, 2025 | H66: Sep 11, 2025 | I66: 227 | J66: Jun 30, 2025 | K66: Yes | L66: Yes
A67: 723 5th Street NE Unit House, Washington, DC 20002 | B67: =_xlfn.XLOOKUP(A67, 'sqft data'!A:A, 'sqft data'!C:C, "Not Found") -> 3000 | C67: =_xlfn.XLOOKUP(A67, 'bedroom data'!A:A, 'bedroom data'!B:B, "Not Found") -> 3 | D67: =_xlfn.XLOOKUP(A67, 'bathroom data'!A:A, 'bathroom data'!B:B, "Not Found") -> 2.5 | E67: =_xlfn.XLOOKUP(A67, 'bedroom data'!A:A, 'bedroom data'!C:C, "Not Found") -> Capitol Hill | F67: Linda | G67: Sep 20, 2025 | H67: Apr 11, 2026 | I67: 195 | J67: Aug 15, 2025 | K67: No | L67: Yes
A68: 723 5th Street NE Unit House, Washington, DC 20002 | B68: =_xlfn.XLOOKUP(A68, 'sqft data'!A:A, 'sqft data'!C:C, "Not Found") -> 3000 | C68: =_xlfn.XLOOKUP(A68, 'bedroom data'!A:A, 'bedroom data'!B:B, "Not Found") -> 3 | D68: =_xlfn.XLOOKUP(A68, 'bathroom data'!A:A, 'bathroom data'!B:B, "Not Found") -> 2.5 | E68: =_xlfn.XLOOKUP(A68, 'bedroom data'!A:A, 'bedroom data'!C:C, "Not Found") -> Capitol Hill | F68: Linda | G68: May 10, 2026 | H68: Jun 09, 2026 | I68: 244 | J68: May 08, 2026 | K68: Yes | L68: No
A69: 723 5th Street NE Unit House, Washington, DC 20002 | B69: =_xlfn.XLOOKUP(A69, 'sqft data'!A:A, 'sqft data'!C:C, "Not Found") -> 3000 | C69: =_xlfn.XLOOKUP(A69, 'bedroom data'!A:A, 'bedroom data'!B:B, "Not Found") -> 3 | D69: =_xlfn.XLOOKUP(A69, 'bathroom data'!A:A, 'bathroom data'!B:B, "Not Found") -> 2.5 | E69: =_xlfn.XLOOKUP(A69, 'bedroom data'!A:A, 'bedroom data'!C:C, "Not Found") -> Capitol Hill | F69: Linda | G69: Jun 11, 2026 | H69: Jul 11, 2026 | I69: 235 | J69: May 11, 2026 | K69: Yes | L69: Yes
A70: 723 5th Street NE Unit House, Washington, DC 20002 | B70: =_xlfn.XLOOKUP(A70, 'sqft data'!A:A, 'sqft data'!C:C, "Not Found") -> 3000 | C70: =_xlfn.XLOOKUP(A70, 'bedroom data'!A:A, 'bedroom data'!B:B, "Not Found") -> 3 | D70: =_xlfn.XLOOKUP(A70, 'bathroom data'!A:A, 'bathroom data'!B:B, "Not Found") -> 2.5 | E70: =_xlfn.XLOOKUP(A70, 'bedroom data'!A:A, 'bedroom data'!C:C, "Not Found") -> Capitol Hill | F70: Linda | G70: Jul 13, 2026 | H70: Aug 14, 2026 | I70: 100 | J70: May 20, 2026 | K70: No | L70: No
A71: 723 5th Street NE Unit Basement, Washington, DC 20002 | B71: =_xlfn.XLOOKUP(A71, 'sqft data'!A:A, 'sqft data'!C:C, "Not Found") -> 900 | C71: =_xlfn.XLOOKUP(A71, 'bedroom data'!A:A, 'bedroom data'!B:B, "Not Found") -> 1 | D71: =_xlfn.XLOOKUP(A71, 'bathroom data'!A:A, 'bathroom data'!B:B, "Not Found") -> 1 | E71: =_xlfn.XLOOKUP(A71, 'bedroom data'!A:A, 'bedroom data'!C:C, "Not Found") -> Capitol Hill | F71: Linda | G71: Apr 26, 2026 | H71: Jul 01, 2026 | I71: 104.11 | J71: Apr 23, 2026 | K71: No | L71: No
A72: 723 5th Street NE Unit Basement, Washington, DC 20002 | B72: =_xlfn.XLOOKUP(A72, 'sqft data'!A:A, 'sqft data'!C:C, "Not Found") -> 900 | C72: =_xlfn.XLOOKUP(A72, 'bedroom data'!A:A, 'bedroom data'!B:B, "Not Found") -> 1 | D72: =_xlfn.XLOOKUP(A72, 'bathroom data'!A:A, 'bathroom data'!B:B, "Not Found") -> 1 | E72: =_xlfn.XLOOKUP(A72, 'bedroom data'!A:A, 'bedroom data'!C:C, "Not Found") -> Capitol Hill | F72: Linda | G72: Jul 04, 2026 | H72: Aug 05, 2026 | I72: 100 | J72: May 20, 2026 | K72: No | L72: No
... A801: 10 Ashby Street Unit D, Alexandria, VA 22305 | B801: =_xlfn.XLOOKUP(A801, 'sqft data'!A:A, 'sqft data'!C:C, "Not Found") -> 700 | C801: =_xlfn.XLOOKUP(A801, 'bedroom data'!A:A, 'bedroom data'!B:B, "Not Found") -> 1 | D801: =_xlfn.XLOOKUP(A801, 'bathroom data'!A:A, 'bathroom data'!B:B, "Not Found") -> 1 | E801: =_xlfn.XLOOKUP(A801, 'bedroom data'!A:A, 'bedroom data'!C:C, "Not Found") -> Alexandria | F801: Sabrina | G801: May 26, 2026 | H801: Nov 26, 2026 | I801: 85 | J801: Apr 28, 2026 | K801: Yes | L801: No

Sheet bathroom data
A1: Property Editor Link | B1: Total Bath | C1: Full Bath | D1: Half Bath
A2: 3329 Q Street NW Unit House, Washington, DC 20007 | B2: =SUM(C2 + 1/2*D2) -> 3.5 | C2: 3 | D2: 1
A3: 6226 Kellogg Dr NW Unit House, McLean, VA 22101 | B3: =SUM(C3 + 1/2*D3) -> 5 | C3: 5 | D3: 0
A4: 1365 Perry Place NW Unit House, Washington, DC 20010 | B4: =SUM(C4 + 1/2*D4) -> 3 | C4: 3 | D4: 0
A5: DNU QQQQ NW Unit -, Washington, DC 20007 | B5: =SUM(C5 + 1/2*D5) -> 6 | C5: 5 | D5: 2
A6: 3333 Q ST NW Unit House, Washington, DC 20007 | B6: =SUM(C6 + 1/2*D6) -> 6 | C6: 5 | D6: 2
A7: 818 19th Street Unit House, Arlington, VA 22202 | B7: =SUM(C7 + 1/2*D7) -> 4.5 | C7: 3 | D7: 3
A8: 1717 P Street NW Unit E, Washington, DC 20036 | B8: =SUM(C8 + 1/2*D8) -> 3 | C8: 3 | D8: 0
A9: 2957 Newark Street NW Unit B, Washington, DC 20008 | B9: =SUM(C9 + 1/2*D9) -> 1 | C9: 1 | D9: 0
A10: DNU - 1740 R Street NW NW Unit 2, Washington DC, DC 20009 | B10: =SUM(C10 + 1/2*D10) -> 1.5 | C10: 1 | D10: 1
A11: 3143 N Street NW Unit 4, Washington, DC 20007 | B11: =SUM(C11 + 1/2*D11) -> 1 | C11: 1 | D11: 0
A12: 1330 35th Street NW Unit House, Washington, DC 20007 | B12: =SUM(C12 + 1/2*D12) -> 4 | C12: 4 | D12: 0
A13: 1155 23rd Street NW Unit 2L, Washington, DC 20037 | B13: =SUM(C13 + 1/2*D13) -> 1.5 | C13: 1 | D13: 1
... A56: 3222 Cherry Hill Lane NW Unit C2, Washington, DC 20007 | B56: =SUM(C56 + 1/2*D56) -> 2 | C56: 2 | D56: 0
A57: 1723 U Street NW Unit bldg, Washington, DC 20009 | B57: =SUM(C57 + 1/2*D57) -> #VALUE! | C57: FourPlusBath | D57: FourPlusBath
A58: test test location NW Unit 123, washington, DC 20005 | B58: =SUM(C58 + 1/2*D58) -> 1 | C58: 1 | D58: 0
A59: 1440 N Street NW Unit 502, Washington, DC 20005 | B59: =SUM(C59 + 1/2*D59) -> 1 | C59: 1 | D59: 0
A60: 2812 29th Place NW Unit B, Washington, DC 20008 | B60: =SUM(C60 + 1/2*D60) -> 1 | C60: 1 | D60: 0
A61: 921 South Carolina Avenue SE Unit Basement, Washington, DC 20003 | B61: =SUM(C61 + 1/2*D61) -> 1 | C61: 1 | D61: 0
A62: 921 South Carolina Avenue SE Unit House, Washington, DC 20003 | B62: =SUM(C62 + 1/2*D62) -> 1.5 | C62: 1 | D62: 1
A63: 2016 Tysons Ridgeline Road Unit 1, Falls Church, VA 22043 | B63: =SUM(C63 + 1/2*D63) -> 3 | C63: 3 | D63: 0
A64: 11 2nd Street NE Unit 106, Washington, DC 20002 | B64: =SUM(C64 + 1/2*D64) -> 1 | C64: 1 | D64: 0
A65: DNU 11 2nd Street NE Unit 106, Washington, DC 20002 | B65: =SUM(C65 + 1/2*D65) -> 1 | C65: 1 | D65: 0
A66: DNU 11 2nd Street NE Unit 106, Washington, DC 20002 | B66: =SUM(C66 + 1/2*D66) -> 1 | C66: 1 | D66: 0
A67: 1330 Fairmont Street NW Unit 1, Washington, DC 20009 | B67: =SUM(C67 + 1/2*D67) -> 1 | C67: 1 | D67: 0
A68: 2216 40th Place NW Unit 4, Washington, DC 20007 | B68: =SUM(C68 + 1/2*D68) -> 1 | C68: 1 | D68: 0
A69: 3143 N Street NW Unit 1, Washington, DC 20007 | B69: =SUM(C69 + 1/2*D69) -> 1 | C69: 1 | D69: 0
... A95: 601 Wharf Street SW Unit 301, Washington, DC 20024 | B95: =SUM(C95 + 1/2*D95) -> 3 | C95: 3 | D95: 0
A96: 3203 Leland Street Unit House, Chevy Chase, MD 20815 | B96: 4 | C96: FourPlusBath | D96: 0
A97: 225 C Street NE Unit 63, Washington, DC 20002 | B97: =SUM(C97 + 1/2*D97) -> 2.5 | C97: 2 | D97: 1
A98: 1213 N Street NW Unit A, Washington, DC 20005 | B98: =SUM(C98 + 1/2*D98) -> 2 | C98: 2 | D98: 0
A99: 935 15th Street SE Unit 1AB, Washington, DC 20003 | B99: =SUM(C99 + 1/2*D99) -> 3 | C99: 3 | D99: 0
A100: 130 S DKsja Unit 1AB, Virginia, DC 20202 | B100: =SUM(C100 + 1/2*D100) -> 1.5 | C100: 1 | D100: 1
A101: 1703 West virginia Unit 1AB, Washington DC, DC 20002 | B101: =SUM(C101 + 1/2*D101) -> 1 | C101: 1 | D101: 0
A102: 1825 Providence Street NE Unit 1AB, Washington, DC 20002 | B102: =SUM(C102 + 1/2*D102) -> 1 | C102: 1 | D102: 0
A103: 1703 West Virginia Ave NE Unit 1AB, Washington, DC 20002 | B103: =SUM(C103 + 1/2*D103) -> 1 | C103: 1 | D103: 0
A104: 1027 Hamlin Street NE Unit 1AB, Washington, DC 20017 | B104: =SUM(C104 + 1/2*D104) -> 1 | C104: 1 | D104: 0
A105: 1300 4th Street SE Unit 213, Washington, DC 20003 | B105: =SUM(C105 + 1/2*D105) -> 2 | C105: 2 | D105: 0
A106: 1528 Swann Street NW Unit 1AB, Washington, DC 20009 | B106: =SUM(C106 + 1/2*D106) -> 3 | C106: 3 | D106: 0
A107: 2126 O Street NW Unit A, Washington, DC 20037 | B107: =SUM(C107 + 1/2*D107) -> 1 | C107: 1 | D107: 0
...

Sheet bedroom data
A1: Property Editor Link | B1: Bedrooms | C1: Neighborhood
A2: 3329 Q Street NW Unit House, Washington, DC 20007 | B2: 3 | C2: Georgetown
A3: 6226 Kellogg Dr NW Unit House, McLean, VA 22101 | B3: 6 | C3: Potomac
A4: 1365 Perry Place NW Unit House, Washington, DC 20010 | B4: 3 | C4: Columbia Heights
A5: DNU QQQQ NW Unit -, Washington, DC 20007 | B5: Studio | C5: Georgetown
A6: 3333 Q ST NW Unit House, Washington, DC 20007 | B6: 4 | C6: Georgetown
A7: 818 19th Street Unit House, Arlington, VA 22202 | B7: 3 | C7: Arlington
A8: 1717 P Street NW Unit E, Washington, DC 20036 | B8: 3 | C8: Dupont Circle
A9: 2957 Newark Street NW Unit B, Washington, DC 20008 | B9: 1 | C9: Cleveland Park
A10: DNU - 1740 R Street NW NW Unit 2, Washington DC, DC 20009 | B10: 1 | C10: Dupont Circle
A11: 3143 N Street NW Unit 4, Washington, DC 20007 | B11: 1 | C11: Georgetown
A12: 1330 35th Street NW Unit House, Washington, DC 20007 | B12: 5 | C12: Georgetown
A13: 1155 23rd Street NW Unit 2L, Washington, DC 20037 | B13: 1 | C13: Dupont /WestEnd
A14: 2650 Woodley Road NW Unit 0231, Washington, DC 20008 | B14: 3 | C14: Adams Morgan
A15: 1806 Vernon Street NW Unit 4, Washington, DC 20009 | B15: 2 | C15: Adams Morgan
A16: 4545 MacArthur NW Unit 107, Washington, DC 20007 | B16: 3 | C16: Palisades
A17: 2428 17th Street NW Unit 3N, Washington, DC 20009 | B17: 2 | C17: Adams Morgan
... A25: 418 D Street SE Unit 3, Washington, DC 20003 | B25: 5 | C25: Capitol Hill
A26: 1711 Massachusetts Ave NW Unit 515, Washington, DC 20036 | B26: Studio | C26: Dupont Circle
A27: 1511 Q Street NW Unit B, Washington, DC 20009 | B27: 1 | C27: Dupont Circle
A28: 1511 Q Street, NW Unit House, Washington, DC 20009 | B28: 2 | C28: Dupont Circle
A29: DNU 5049 Garfield St NW Unit House, Washington, DC 20016 | B29: 4 | C29: Palisades
A30: 3143 N Street NW Unit 2, Washington, DC 20007 | B30: 1 | C30: Georgetown
A31: 1743 Q St NW Unit House, Washington, DC 20009 | B31: 4 | C31: Dupont Circle
A32: 5049 Garfield Street NW Unit House, Washington, DC 20016 | B32: 4 | C32: Palisades
A33: 1016 29th Street NW Unit House, Washington, DC 20007 | B33: 2 | C33: Georgetown
A34: THIS IS THE DO NOT USE - 1016 29th St NW Unit House, Washington, DC 20007 | B34: 2 | C34: Georgetown
A35: 816 Potomac Avenue SE Unit Townhouse, Washington, DC 20003 | B35: 2 | C35: Navy Yard
A36: 816 Potomac Avenue SE Unit 303, Washington, DC 20003 | B36: 2 | C36: Navy Yard
A37: 816 Potomac Avenue SE Unit 302, Washington, DC 20003 | B37: 2 | C37: Navy Yard
A38: 1754 Park Road NW Unit House, Washington, DC 20010 | B38: 4 | C38: Mt Pleasant
... A45: 22 Seaton Place NW Unit 1AB, Washington, DC 20001 | B45: 3 | C45: Bloomingdale
A46: 2516 Q Street NW Unit 304, Washington, DC 20007 | B46: Studio | C46: Georgetown
A47: Testing street NW Unit 123, testing city, DC 22209 | B47: 1 | C47: Arlington
A48: 1115 M Street NW Unit 2, Washington, DC 20005 | B48: 1 | C48: Logan Circle
A49: 2439 18th Street NW Unit 4, Washington DC, DC 20009 | B49: 2 | C49: Adams Morgan
A50: 2439 18th Street NW Unit 3, Washington DC, DC 20009 | B50: 2 | C50: Adams Morgan
A51: 221 8th St NE Unit House, Washington, DC 20002 | B51: 3 | C51: Capitol Hill
A52: Testing Unit a1, testing, 09 20005 | B52: 1 | C52: Dupont Circle
A53: 1822 15th Street NW Unit B1, Washington, DC 20009 | B53: Studio | C53: Dupont Circle
...

Sheet sqft data
A1: Property | B1: Property ID | C1: Square Footage
A2: 3329 Q Street NW Unit House, Washington, DC 20007 | B2: 1222 | C2: 1452
A3: 1365 Perry Place NW Unit House, Washington, DC 20010 | B3: 1221 | C3: 1280
A4: 3333 Q ST NW Unit House, Washington, DC 20007 | B4: 1220 | C4: 5120
A5: 1717 P Street NW Unit E, Washington, DC 20036 | B5: 0 | C5: 2300
A6: 2957 Newark Street NW Unit B, Washington, DC 20008 | B6: 1225 | C6: 700
A7: 3143 N Street NW Unit 4, Washington, DC 20007 | B7: 1219 | C7: 700
A8: 1806 Vernon Street NW Unit 4, Washington, DC 20009 | B8: 1214 | C8: 1100
A9: 4545 MacArthur NW Unit 107, Washington, DC 20007 | B9: 1210 | C9: 763
A10: 2428 17th Street NW Unit 3N, Washington, DC 20009 | B10: 1215 | C10: 1600
A11: 88 V Street SW Unit 203, Washington, DC 20024 | B11: 1209 | C11: 882
A12: 1459 S Street NW Unit 2, Washington, DC 20009 | B12: 1204 | C12: 2100
A13: 3901 Cathedral Avenue NW Unit 209, Washington, DC 20016 | B13: 1208 | C13: 600
... A165: 1822 15th Street NW Unit 301, Washington, DC 20009 | B165: 63 | C165: 318
